Workbook

Sheet Jan 2023
E2: Jan 2023 Sales in Nutsell
E3: Grades | F3: Off Grade | G3: 1799 | H3: 2099 | I3: 2699 | J3: 588 | K3: 2088 | L3: 2488 | M3: 2688 | N3: TOTAL
E4: Qty | F4: ='Jan 2023'!$J$53 -> 6980 | G4: ='Jan 2023'!$K$53 -> 23100 | H4: ='Jan 2023'!$L$53 -> 950 | I4: ='Jan 2023'!$M$53 -> 1275 | J4: ='Jan 2023'!$N$53 -> 1100 | K4: ='Jan 2023'!$O$53 -> 0 | L4: ='Jan 2023'!$P$53 -> 600 | M4: ='Jan 2023'!$Q$53 -> 3950 | N4: =SUM(F4:M4) -> 37955
E5: Avg Sales PK
E6: Profit PK
E7: Total
D11: Srl No | E11: Date | F11: Inv No | G11: Party | H11: Qty | I11: Price | J11: Off Grade | K11: 1799 | L11: 2099 | M11: 2699 | N11: 588 | O11: 2088 | P11: 2488 | Q11: 2688
D12: 1 | E12: 44928 | F12: 258 | G12: Darshan | H12: 220 | I12: 160 | J12: 220
D13: 2 | E13: 44928 | F13: 259 | G13: Giriraj | H13: 1000 | I13: 228 | Q13: 1000
D14: 3 | E14: 44928 | F14: 260 | G14: Giriraj | H14: 3000 | I14: 150 | J14: 3000
D15: 4 | E15: 44928 | F15: 261 | G15: Chemicare | H15: 6200 | I15: 200 | K15: 6200
D16: 5 | E16: 44929 | F16: 58 GTC | G16: SKS Fine | H16: 250 | I16: 220 / 225 | M16: 50 | P16: 200
D17: 6 | E17: 44930 | F17: 263 | G17: Seamless | H17: 200 | I17: 230 | Q17: 200
D18: 7 | E18: 44935 | F18: RR | G18: Meet Sach | H18: 600 | I18: 204 / 216 | L18: 400 | M18: 200
D19: 8 | E19: 44935 | F19: RR | G19: Shri Ganpatye | H19: 500 | I19: 225 | Q19: 500
D20: 9 | E20: 44936 | F20: 60 GTC | G20: Veena | H20: 425 | I20: 227 / 220 | M20: 25 | P20: 400
D21: 10 | E21: 44939 | F21: 62 GTC | G21: Chandan Syn | H21: 500 | I21: 204 | L21: 500
D22: 11 | E22: 44939 | F22: 63 gtc | G22: Fortune | H22: 250 | I22: 230 | Q22: 250
D23: 12 | E23: 44944 | F23: RR | G23: Santosh | H23: 50 | I23: 240 | L23: 50
D24: 13 | E24: 44945 | F24: 268 | G24: Dhiren Enter | H24: 100 | I24: 235 | N24: 100
D25: 14 | E25: 44946 | F25: 269 | G25: Papyrus | H25: 500 | I25: 160 | J25: 500
D26: 15 | E26: 44947 | F26: 271 | G26: Indokem | H26: 5000 | I26: 205 | K26: 5000
D27: 16 | E27: 44949 | F27: RR | G27: Meet Sach | H27: 400 | I27: 204 | K27: 400
D28: 17 | E28: 44949 | F28: 64 GTC | G28: AP Bonding | H28: 1000 | I28: 216 | N28: 1000
D29: 18 | E29: 44953 | F29: 275 | G29: Surya | H29: 2000 | I29: 225 | Q29: 2000
D30: 19 | E30: 44953 | F30: RR | G30: Hareshji | H30: 500 | I30: 212 | M30: 500
D31: 20 | E31: 44953 | F31: 276 | G31: Chandan Syn | H31: 3000 | I31: 160 | J31: 3000
D32: 21 | E32: 44954 | F32: 277 | G32: Mangalam Dye | H32: 278 | I32: 160 | J32: 260
D33: 22 | E33: 44954 | F33: 279 | G33: Fortune | H33: 500 | I33: 220 | M33: 500
D34: 23 | E34: 44957 | F34: 280 | G34: Indokem | H34: 11500 | I34: 205 | K34: 11500
D53: TOTAL | H53: =SUM(H12:H52) -> 37973 | J53: =SUM('Jan 2023'!$J$12:$J$52) -> 6980 | K53: =SUM('Jan 2023'!$K$12:$K$52) -> 23100 | L53: =SUM('Jan 2023'!$L$12:$L$52) -> 950 | M53: =SUM('Jan 2023'!$M$12:$M$52) -> 1275 | N53: =SUM('Jan 2023'!$N$12:$N$52) -> 1100 | O53: =SUM('Jan 2023'!$O$12:$O$52) -> 0 | P53: =SUM('Jan 2023'!$P$12:$P$52) -> 600 | Q53: =SUM('Jan 2023'!$Q$12:$Q$52) -> 3950

Sheet Feb 2023
D3: Feb 2023 Sales in Nutsell
D4: Grades | E4: Off Grade | F4: 1799 | G4: 2099 | H4: 2699 | I4: 588 | J4: 2088 | K4: 2488 | L4: 2688 | M4: TOTAL
D5: Qty | E5: ='Feb 2023'!$I$54 -> 16330 | F5: ='Feb 2023'!$J$54 -> 1100 | G5: ='Feb 2023'!$K$54 -> 1300 | H5: ='Feb 2023'!$L$54 -> 4820 | I5: ='Feb 2023'!$M$54 -> 1000 | J5: ='Feb 2023'!$N$54 -> 8925 | K5: ='Feb 2023'!$O$54 -> 3660 | L5: ='Feb 2023'!$P$54 -> 600 | M5: =SUM(E5:L5) -> 37735
D6: Avg Sales PK
D7: Profit PK
D8: Total
C12: Srl No | D12: Date | E12: Inv No | F12: Party | G12: Qty | H12: Price | I12: Off Grade | J12: 1799 | K12: 2099 | L12: 2699 | M12: 588 | N12: 2088 | O12: 2488 | P12: 2688
C13: 1 | D13: 44958 | E13: 282 | F13: KDM | G13: 60 | H13: 160 | I13: 60
C14: 2 | D14: 44961 | E14: 283 | F14: Aditya | G14: 1500 | H14: 205 | L14: 1500
C15: 3 | D15: 44961 | E15: 284 | F15: Veena | G15: 400 | H15: 225 | O15: 400
C16: 4 | D16: 44596 | E16: RR | F16: Meet Sach | G16: 500 | H16: 205/206 | J16: 200 | K16: 300
C17: 5 | D17: 44964 | E17: 287 | F17: Can Image | G17: 500 | H17: 220 | N17: 500
C18: 6 | D18: 44966 | E18: 288 | F18: Paramount | G18: 10000 | H18: 150 | I18: 10000
C19: 7 | D19: 44966 | E19: 289 | F19: Can Image | G19: 1000 | H19: 225 / 230 | O19: 500 | P19: 500
C20: 8 | D20: 44966 | E20: RR | F20: Naveen Bhai | G20: 700 | H20: 155 | I20: 700
C21: 9 | D21: 44967 | E21: 291 | F21: Bhavya Enter | G21: 900 | H21: 201 | J21: 900
C22: 10 | D22: 44968 | E22: 292 | F22: Darshan | G22: 200 | H22: 160 | I22: 200
C23: 11 | D23: 44968 | E23: 295 | F23: Jay Organics | G23: 100 | H23: 160 | I23: 160
C24: 12 | D24: 44968 | E24: 296 | F24: Can Image | G24: 5000 | H24: 216 | N24: 5000
C25: 13 | D25: 44968 | E25: 297 | F25: Kanha Trading | G25: 200 | H25: 160 | I25: 200
C26: 14 | D26: 44970 | E26: 298 | F26: Keval Corp | G26: 50 | H26: 217 | O26: 50
C27: 15 | D27: 44970 | E27: RR | F27: Meet Sach | G27: 300 | H27: 155 | I27: 300
C28: 16 | D28: 44971 | E28: 67 GTC | F28: Veena | G28: 500 | H28: 225 | O28: 500
C29: 17 | D29: 44972 | E29: 299 | F29: Paresh Pure Chem | G29: 250 | H29: 150 | I29: 250
C30: 18 | D30: 44972 | E30: 301 | F30: Papyrus | G30: 500 | H30: 150 | I30: 500
C31: 19 | D31: 44972 | E31: 300 | F31: Suncol | G31: 760 | H31: 160 | I31: 760
C32: 20 | D32: 44972 | E32: 302 | F32: Paresh Pure Chem | G32: 200 | H32: 160 | I32: 200
C33: 21 | D33: 44972 | E33: 303, 304 | F33: BSB Inds | G33: 4000 | H33: 150, 204, 213 | I33: 2000 | K33: 500 | L33: 1500
C34: 22 | D34: 44977 | E34: 305 | F34: KDM | G34: 200 | H34: 160 | I34: 200
C35: 23 | D35: 44977 | E35: 306 | F35: Devankshi | G35: 1000 | H35: 215 | N35: 1000
C36: 24 | D36: 44977 | E36: 307 | F36: Devankshi | G36: 1200 | H36: 216 | N36: 1200
C37: 25 | D37: 44977 | E37: RR | F37: Meet Sach | G37: 100 | H37: 215 | L37: 100
C38: 26 | D38: 44977 | E38: 308 | F38: Aditya | G38: 1000 | H38: 220 | M38: 1000
C39: 27 | D39: 44979 | E39: 309 | F39: Neelam | G39: 500 | H39: 220 | O39: 220
C40: 28 | D40: 44981 | E40: 311 | F40: Can Image | G40: 3000 | H40: 216, 220 | N40: 1225 | O40: 1775
C41: 29 | D41: 44981 | E41: 68 GTC | F41: Fortune | G41: 250 | H41: 220 | L41: 220
C42: 30 | D42: 44984 | E42: 313 | F42: Paresh Pure Chem | G42: 500 | H42: 155 | I42: 500
C43: 31 | D43: 44984 | E43: 314 | F43: Seamless | G43: 100 | H43: 230 | P43: 100
C44: 32 | D44: 44984 | E44: RR | F44: Gurpreet | G44: 500 | H44: 210 | K44: 500
C45: 33 | D45: 44984 | E45: 69 GTC | F45: Aditya | G45: 1500 | H45: 214 | L45: 1500
...

Sheet March 2023
D2: March 2023 Sales in Nutsell
D3: Grades | E3: Off Grade | F3: 1799 | G3: 2099 | H3: 2699 | I3: 588 | J3: 2088 | K3: 2488 | L3: 2688 | M3: TOTAL
D4: Qty | E4: ='March 2023'!$I$53 -> 6525 | F4: ='March 2023'!$J$53 -> 11500 | G4: ='March 2023'!$K$53 -> 25 | H4: ='March 2023'!$L$53 -> 4600 | I4: ='March 2023'!$M$53 -> 50 | J4: ='March 2023'!$N$53 -> 7450 | K4: ='March 2023'!$O$53 -> 8000 | L4: ='March 2023'!$P$53 -> 2200 | M4: =SUM(E4:L4) -> 40350
D5: Avg Sales PK
D6: Profit PK
D7: Total
C11: Srl No | D11: Date | E11: Inv No | F11: Party | G11: Qty | H11: Price | I11: Off Grade | J11: 1799 | K11: 2099 | L11: 2699 | M11: 588 | N11: 2088 | O11: 2488 | P11: 2688
C12: 1 | D12: 44986 | E12: 319 | F12: Neelam | G12: 150 | H12: 214 | L12: 150
C13: 2 | D13: 44986 | E13: 321 | F13: Giriraj | G13: 3000 | H13: 155 | I13: 3000
C14: 3 | D14: 44987 | E14: RR | F14: Patidar | G14: 1000 | H14: 214 | L14: 1000
C15: 4 | D15: 44989 | E15: 70 GTC | F15: Veena | G15: 500 | H15: 225 | O15: 500
C16: 5 | D16: 44989 | E16: 71 GTC | F16: AP Bonding | G16: 2000 | H16: 213 | O16: 2000
C17: 6 | D17: 44989 | E17: 323 | F17: AP Enterprises | G17: 150 | H17: 225 | L17: 150
C18: 7 | D18: 44994 | E18: 325 | F18: Can Image | G18: 5000 | H18: 220 | O18: 5000
C19: 8 | D19: 44994 | E19: 73 GTC | F19: Fortune | G19: 250 | H19: 220 | L19: 250
C20: 9 | D20: 44995 | E20: 327 | F20: VijayRaj | G20: 225 | H20: 155 | I20: 225
C21: 10 | D21: 44996 | E21: 328 | F21: Paresh Pure Chem | G21: 500 | H21: 150 | I21: 500
C22: 11 | D22: 44998 | E22: RR | F22: Meet Sach | G22: 700 | H22: 155 | I22: 700
C23: 12 | D23: 44998 | E23: 74 GTC | F23: Aditya | G23: 1000 | H23: 218 | L23: 1000
C24: 13 | D24: 44996 | E24: 329 | F24: Kanha Trading | G24: 200 | H24: 150 | I24: 200
C25: 14 | D25: 44998 | E25: 331 | F25: Mine Chem | G25: 25 | H25: 210 | K25: 25
C26: 15 | D26: 45001 | E26: RR | F26: Meet Sach | G26: 300 | H26: 217 | L26: 300
C27: 16 | D27: 45002 | E27: 76 GTC | F27: Aditya | G27: 10000 | H27: 203 | J27: 11000
C28: 17 | D28: 45003 | E28: RR | F28: Shri Ganpatye | G28: 200 | H28: 230 | P28: 200
C29: 18 | D29: 45003 | E29: 332 | F29: Surya | G29: 2000 | H29: 220 | P29: 2000
C30: 19 | D30: 45000 | E30: 333 | F30: Divysai | G30: 250 | H30: 212 | N30: 250
C31: 20 | D31: 45005 | E31: 334 | F31: Papyrus | G31: 1250 | H31: 153 | I31: 1250
C32: 21 | D32: 45006 | E32: 335 | F32: Chemie Care | G32: 2000 | H32: 210 | N32: 2000
C33: 22 | D33: 45008 | E33: 339 | F33: Superbond | G33: 500 | H33: 200 | J33: 500
C34: 23 | D34: 45008 | E34: 340 | F34: Can Image | G34: 5000 | H34: 216 | N34: 5000
C35: 24 | D35: 45008 | E35: 78 GTC | F35: Fortune | G35: 250 | H35: 220 | L35: 250
C36: 25 | D36: 45012 | E36: 360 | F36: Paresh Pure Chem | G36: 260 | H36: 150 | I36: 250
C37: 26 | D37: 45012 | E37: 361 | F37: SKS Fine | G37: 200 | H37: 218 | N37: 200
C38: 27 | D38: 45012 | E38: 362 | F38: KDM | G38: 400 | H38: 155 | I38: 400
C39: 28 | D39: 45012 | E39: 90 GTC | F39: Aditya | G39: 1500 | H39: 215 | L39: 1500
C40: 29 | D40: 45012 | E40: 68 GTC | F40: Veena | G40: 550 | H40: 220 | M40: 50 | O40: 500
C41: 30 | F41: Paresh Pure Chem
C42: 31 | F42: Seamless
C43: 32 | F43: Gurpreet
C44: 33 | F44: Aditya
...

Sheet April 2023
D2: April 2023 Sales in Nutsell | O2: Prime
D3: Grades | E3: Off Grade | F3: 1799 | G3: 2099 | H3: 2699 | I3: 588 | J3: 2088 | K3: 2488 | L3: 2688 | M3: TOTAL
D4: Qty | E4: ='April 2023'!$I$65 -> 86300 | F4: ='April 2023'!$J$65 -> 39475 | G4: ='April 2023'!$K$65 -> 325 | H4: ='April 2023'!$L$65 -> 3250 | I4: ='April 2023'!$M$65 -> 0 | J4: ='April 2023'!$N$65 -> 10550 | K4: ='April 2023'!$O$65 -> 5650 | L4: ='April 2023'!$P$65 -> 8000 | M4: =SUM(E4:L4) -> 153550 | O4: =SUM(F4:L4) -> 67250
D5: Avg Sales PK
D6: Profit PK
D7: Total
C11: Srl No | D11: Date | E11: Inv No | F11: Party | G11: Qty | H11: Price | I11: Off Grade | J11: 1799 | K11: 2099 | L11: 2699 | M11: 588 | N11: 2088 | O11: 2488 | P11: 2688
C12: 1 | D12: 45017 | E12: 1 | F12: SKS Fine | G12: 500 | H12: 150 | I12: 500
C13: 2 | D13: 45017 | E13: 2 | F13: Sagar Corp | G13: 1500 | H13: 145 | I13: 1500
C14: 3 | D14: 45017 | E14: 3 | F14: BSB Indus | G14: 1000 | H14: 208 | L14: 1000
C15: 4 | D15: 45017 | E15: RR | F15: Gurpreet | G15: 500 | H15: 210, 215 | K15: 250 | L15: 250
C16: 5 | D16: 45017 | E16: 1 GTC | F16: Aditya | G16: 7000 | H16: 202, 204 | J16: 5000 | O16: 2000
C17: 6 | D17: 45017 | E17: 2 GTC | F17: AP Bond | G17: 3000 | H17: 202 | J17: 3000
C18: 7 | D18: 45018 | E18: 5 | F18: Siva Chem | G18: 10000 | H18: 140 | I18: 10000
C19: 8 | D19: 45019 | E19: 6 | F19: Paresh Pure Chem | G19: 200 | H19: 148 | I19: 200
C20: 9 | D20: 45020 | E20: 8 | F20: Deepak Enterprise | G20: 1500 | H20: 208 | P20: 1500
C21: 10 | D21: 45021 | E21: 10 | F21: Seamless | G21: 100 | H21: 225 | P21: 100
C22: 11 | D22: 45021 | E22: RR | F22: Meet Sach | G22: 700 | H22: 203, 155 | I22: 300 | J22: 400
C23: 12 | D23: 45021 | E23: 11 | F23: SKS Fine | G23: 700 | H23: 150, 210 | I23: 500 | L23: 200
C24: 13 | D24: 45021 | E24: 13 | F24: Ankush Enterprise | G24: 1000 | H24: 208 | L24: 1000
C25: 14 | D25: 45021 | E25: 15 | F25: Jai Aravali | G25: 5000 | H25: 201 | J25: 5000
C26: 15 | D26: 45021 | E26: 16 | F26: Fortune | G26: 500 | H26: 220 | L26: 500
C27: 16 | D27: 45022 | E27: 18 | F27: Divysai | G27: 200 | H27: 204 | O27: 200
C28: 17 | D28: 45022 | E28: 19 | F28: Rajasthan Det | G28: 1000 | H28: 135 | I28: 1000
C29: 18 | D29: 45022 | E29: 21 | F29: Jai Aravali | G29: 5000 | H29: 201 | J29: 5000
C30: 19 | D30: 45023 | E30: 3 GTC | F30: Aditya | G30: 5000 | H30: 203 | N30: 3000 | O30: 2000
C31: 20 | D31: 45023 | E31: 22 | F31: BSB Indus | G31: 3000 | H31: 130 | I31: 3000
C32: 21 | D32: 45023 | E32: 23 | F32: BSB Indus | G32: 1000 | H32: 230 | P32: 1000
C33: 22 | D33: 45024 | E33: 24 | F33: Paresh Pure Chem | G33: 460 | H33: 148 | I33: 460
C34: 23 | D34: 45024 | E34: 25 | F34: Mangalam | G34: 200 | H34: 150 | I34: 200
C35: 24 | D35: 45024 | E35: 26 | F35: BSB Indus | G35: 500 | H35: 140 | I35: 500
C36: 25 | D36: 45024 | E36: 27 | F36: Fortune | G36: 100 | H36: 230 | P36: 100
C37: 26 | D37: 45026 | E37: 29 | F37: Alpha Resources | G37: 500 | H37: 202 | J37: 500
C38: 27 | D38: 45027 | E38: 31 | F38: Siva Chem | G38: 10000 | H38: 140 | I38: 10000
C39: 28 | D39: 45030 | E39: 33 | F39: Divysai | G39: 200 | H39: 206 | O39: 200
C40: 29 | D40: 45030 | E40: RR | F40: Shri Ganpatye | G40: 200 | H40: 230 | P40: 200
C41: 30 | D41: 45027 | E41: 7 | F41: Rudolf | G41: 26000 | H41: 180.4 | I41: 26000
C42: 31 | D42: 45031 | E42: 34 | F42: Sagar Corp | G42: 200 | H42: 145 | I42: 200
C43: 32 | D43: 45031 | E43: RR | F43: Meet Sach | G43: 300 | H43: 213 | L43: 300
C44: 33 | D44: 45031 | E44: 35 | F44: Paramount | G44: 11300 | H44: 140 | I44: 11300
...

Sheet May 2023
D3: May 2023 Sales in Nutsell | O3: Prime | P3: Off Grade | Q3: Total
D4: Grades | E4: Off Grade | F4: 1799 | G4: 2099 | H4: 2699 | I4: 588 | J4: 2088 | K4: 2488 | L4: 2688 | M4: TOTAL
D5: Qty | E5: ='May 2023'!$I$69 -> 33780 | F5: ='May 2023'!$J$69 -> 10000 | G5: ='May 2023'!$K$69 -> 0 | H5: ='May 2023'!$L$69 -> 8800 | I5: ='May 2023'!$M$69 -> 3500 | J5: ='May 2023'!$N$69 -> 13475 | K5: ='May 2023'!$O$69 -> 14550 | L5: ='May 2023'!$P$69 -> 5100 | M5: =SUM(E5:L5) -> 89205 | O5: =SUM(F5:L5) -> 55425 | P5: =E5 -> 33780 | Q5: =SUM(O5,P5) -> 89205
D6: Avg Sales PK
D7: Profit PK
D8: Total
C12: Srl No | D12: Date | E12: Inv No | F12: Party | G12: Qty | H12: Price | I12: Off Grade | J12: 1799 | K12: 2099 | L12: 2699 | M12: 588 | N12: 2088 | O12: 2488 | P12: 2688 | S12: Off Grade Stocks And Sales
C13: 1 | D13: 45049 | E13: 13 GTC | F13: Doshi | G13: 1500 | H13: 196 | P13: 1500 | S13: Srl No. | T13: Date | U13: Details | V13: Qty | W13: New Stock | X13: Qty | Y13: Total | Z13: Date Sales | AA13: Party | AB13: Qty | AC13: Product | AD13: Bal Stock
C14: 2 | D14: 45048 | E14: 57 | F14: Doshi | G14: 1500 | H14: 135 | I14: 1500 | S14: 1 | T14: 45060 | U14: Lot of 50 MT | V14: 500 | Z14: 45064 | AA14: Siva Chem | AB14: 8500 | AC14: Siva Chem | AD14: nil
C15: 3 | D15: 45049 | E15: 59 | F15: Papyrus | G15: 500 | H15: 145 | I15: 500 | S15: 2 | T15: 45060 | U15: Eco Ind | V15: 2500 | Z15: 45064 | AA15: Siva Chem | AB15: 1000 | AC15: 325 usa | AD15: 27000
C16: 4 | D16: 45049 | E16: 60,61 | F16: Chandan | G16: 200 | H16: 150, 206 | I16: 100 | P16: 100 | S16: 3 | T16: 45060 | U16: Germany | V16: 52000 | Z16: 45064 | AA16: Siva Chem | AB16: 1000 | AC16: Germany | AD16: 51000
C17: 5 | D17: 45049 | E17: 62 | F17: Fortune | G17: 250 | H17: 210 | L17: 250 | S17: 4 | T17: 45060 | U17: Japan Crab | V17: 8000 | Z17: 45064 | AA17: Siva Chem | AB17: 3500 | AC17: Japan | AD17: 4500
C18: 6 | D18: 45050 | E18: 64 | F18: Vrinda | G18: 2000 | H18: 140 | I18: 2000 | S18: 5 | T18: 45060 | U18: Siva Chem | V18: 8500 | Z18: 45065 | AA18: Sagar Corp | AB18: 1000 | AC18: 13/5 USA | AD18: 36500
C19: 7 | D19: 45050 | E19: RR | F19: Meet Sach | G19: 500 | H19: 197 | J19: 500 | S19: 6 | T19: 45060 | U19: 523 USA | V19: 5000 | Z19: 45065 | AA19: Paresh Pure | AB19: 1200 | AC19: 13/5 USA | AD19: 35300
C20: 8 | D20: 45050 | E20: 65 | F20: Kanha | G20: 200 | H20: 135 | I20: 200 | S20: 7 | T20: 45060 | U20: 325 USA | V20: 27000 | Z20: 45065 | AA20: KDM | AB20: 700 | AC20: 13/5 USA | AD20: 34600
C21: 9 | D21: 45051 | E21: 66 | F21: Sagar Dye | G21: 1000 | H21: 193 | O21: 1000 | S21: 8 | T21: 45060 | U21: 13/5 USA | V21: 37500 | Z21: 45066 | AA21: Paresh Pure | AB21: 500 | AC21: Germany | AD21: 50500
C22: 10 | D22: 45051 | E22: 67 | F22: Raj Chem | G22: 2000 | H22: 200 | L22: 2000 | S22: 9 | T22: 45077 | U22: USA Crystal | V22: 16293 | Z22: 45077 | AA22: Jay, SKR, Mine | AB22: 480 | AC22: Misc
C23: 11 | D23: 45051 | E23: 14 GTC | F23: Aditya | G23: 1500 | H23: 206 | M23: 1500
C24: 12 | D24: 45051 | E24: 68 | F24: PCL | G24: 1000 | H24: 205 | P24: 1000
C25: 13 | D25: 45051 | E25: 15 GTC | F25: Surya | G25: 2000 | H25: 220 | P25: 2000
C26: 14 | D26: 45051 | E26: 69 | F26: Siva Chem | G26: 10000 | H26: 140 | I26: 10000
C27: 15 | D27: 45054 | E27: 71 | F27: Ankush | G27: 1000 | H27: 203 | M27: 1000
C28: 16 | D28: 45054 | E28: 72 | F28: Mine Chem | G28: 600 | H28: 137 | I28: 600
C29: 17 | D29: 45054 | E29: 73 | F29: SKS Fine | G29: 700 | H29: 140, 204 | I29: 500 | O29: 200
C30: 18 | D30: 45055 | E30: GTC 18 | F30: AP Bond | G30: 4000 | H30: 196 | O30: 4000
C31: 19 | D31: 45055 | E31: GTC 19 | F31: Aditya | G31: 5000 | H31: 198, 202, 203 | L31: 2000 | N31: 2000 | O31: 1000
C32: 20 | D32: 45057 | E32: RR | F32: Shri Ganpatye | G32: 250 | H32: 215, 210 | L32: 50 | P32: 200
C33: 21 | D33: 45057 | E33: GTC 20 | F33: Veena | G33: 500 | H33: 204 | O33: 500
C34: 22 | D34: 45054 | E34: 74 | F34: AP Enterprise | G34: 200 | H34: 220 | P34: 200
C35: 23 | D35: 45057 | E35: 75 | F35: Indokem | G35: 5000 | H35: 204 | J35: 5000
C36: 24 | D36: 45057 | E36: RR | F36: Meet Sach | G36: 500 | H36: 144 | I36: 500 | V36: =SUM(V14:V35) -> 157293 | AB36: =SUM(AB14:AB35) -> 17880 | AD36: =SUM(V36-AB36) -> 139413
C37: 25 | D37: 45061 | E37: 76 | F37: Divysai | G37: 200 | H37: 195 | O37: 200
C38: 26 | D38: 45062 | E38: 77 | F38: Sagar Dye | G38: 100 | H38: 197 | O38: 100
C39: 27 | D39: 45063 | E39: 79 | F39: Fortune | G39: 500 | H39: 210 | L39: 500
C40: 28 | D40: 45064 | E40: 81 | F40: Sagar Dye | G40: 500 | H40: 193 | O40: 500
C41: 29 | D41: 45064 | E41: 82 | F41: Siva Chem | G41: 8500 | H41: 140 | I41: 8500
C42: 30 | D42: 45064 | E42: 83 | F42: Siva Chem | G42: 1000 | H42: 145 | I42: 1000
C43: 31 | D43: 45064 | E43: 84 | F43: Siva Chem | G43: 4500 | H43: 140 | I43: 4500
C44: 32 | D44: 45065 | E44: 86 | F44: Seamless | G44: 100 | H44: 225 | P44: 100
C45: 33 | D45: 45065 | E45: 87 | F45: Sagar Corp | G45: 1000 | H45: 135 | I45: 1000
...

Sheet June 2023
D4: May 2023 Sales in Nutsell | O4: Prime | P4: Off Grade | Q4: Total
D5: Grades | E5: Off Grade | F5: 1799 | G5: 2099 | H5: 2699 | I5: 588 | J5: 2088 | K5: 2488 | L5: 2688 | M5: TOTAL
D6: Qty | E6: ='June 2023'!$I$84 -> 37820 | F6: ='June 2023'!$J$84 -> 12975 | G6: ='June 2023'!$K$84 -> 0 | H6: ='June 2023'!$L$84 -> 6875 | I6: ='June 2023'!$M$84 -> 1050 | J6: ='June 2023'!$N$84 -> 3025 | K6: ='June 2023'!$O$84 -> 4400 | L6: ='June 2023'!$P$84 -> 10350 | M6: =SUM(E6:L6) -> 76495 | O6: =SUM(F6:L6) -> 38675 | P6: =E6 -> 37820 | Q6: =SUM(O6,P6) -> 76495
D7: Avg Sales PK
D8: Profit PK
D9: Total
C13: Srl No | D13: Date | E13: Inv No | F13: Party | G13: Qty | H13: Price | I13: Off Grade | J13: 1799 | K13: 2099 | L13: 2699 | M13: 588 | N13: 2088 | O13: 2488 | P13: 2688 | S13: Off Grade Stocks And Sales
C14: 1 | D14: 45078 | E14: 116 | F14: Popular Chemical | G14: 500 | H14: 189 | J14: 500 | S14: New Input
C15: 2 | D15: 45078 | E15: 118 | F15: SKS Fine | G15: 200 | H15: 201 | O15: 200 | S15: Srl No. | T15: Date | U15: Details | V15: Qty
C16: 3 | D16: 45078 | E16: 119 | F16: Divysai | G16: 400 | H16: 189 | O16: 400 | S16: 1 | T16: 45122 | U16: Return From Dhawan | V16: 7200
C17: 4 | D17: 45079 | E17: 120 | F17: Surya | G17: 2000 | H17: 215 | P17: 2000 | S17: 2
C18: 5 | D18: 45079 | E18: 121 | F18: Mangalam | G18: 245 | H18: 135, 190 | I18: 120 | O18: 125 | S18: 3
C19: 6 | D19: 45079 | E19: 122 | F19: Akshat | G19: 145 | H19: 135, 200 | I19: 120 | L19: 25 | S19: 4
C20: 7 | D20: 45079 | E20: 124 | F20: Uma Agencies | G20: 1000 | H20: 176 | J20: 1000 | S20: 5
C21: 8 | D21: 45079 | E21: 125 | F21: A to Z | G21: 1000 | H21: 174 | J21: 1000 | S21: 6
C22: 9 | D22: 45079 | E22: 126 | F22: Shubham Corp | G22: 500 | H22: 197 | P22: 500 | S22: 7
C23: 10 | D23: 45079 | E23: RR | F23: Meet Sach | G23: 300 | H23: 135 | I23: 300 | S23: 8
C24: 11 | D24: 45079 | E24: RR | F24: Shri Ganpatye | G24: 250 | H24: 206 | O24: 50 | P24: 200
C25: 12 | D25: 45080 | E25: 132 | F25: Pappyrus | G25: 460 | H25: 140, 204 | I25: 360 | L25: 100 | S25: Total New Input:- | V25: =SUM(V16:V23) -> 7200
C26: 13 | D26: 45082 | E26: 134 | F26: Bio Chem | G26: 200 | H26: 199 | N26: 200 | S26: Old Stock C/F:- | V26: 139413
C27: 14 | D27: 45082 | E27: 135 | F27: Paramount | G27: 5000 | H27: 125 | I27: 5000 | S27: Total Stocks New & Old :- | V27: =SUM(V25,V26) -> 146613
C28: 15 | D28: 45083 | E28: 136 | F28: Fortune | G28: 625 | H28: 205, 220 | L28: 500 | P28: 125 | S28: LESS SALES: (as per sales sheet) | V28: ='June 2023'!$I$84 -> 37820
C29: 16 | D29: 45083 | E29: 137 | F29: Dipali | G29: 2000 | H29: 187 | P29: 2000
C30: 17 | D30: 45083 | E30: 138 | F30: Siva Chem | G30: 1000 | H30: 144 | I30: 1000 | S30: NET QTY AVAILABLE: | V30: =SUM(V27-V28) -> 108793
C31: 18 | D31: 45083 | E31: 139 | F31: Giriraj | G31: 1000 | H31: 192, 202 | O31: 600 | P31: 400
C32: 19 | D32: 45083 | E32: 140 | F32: Guruji | G32: 1000 | H32: 132, 192 | I32: 1000 | P32: 500
C33: 20 | D33: 45083 | E33: 141 | F33: Popular Chemical | G33: 50 | H33: 180 | J33: 50
C34: 21 | D34: 45083 | E34: 142 | F34: Pearl | G34: 1000 | H34: 182 | O34: 1000
C35: 22 | D35: 45083 | E35: 143 | F35: Chandan | G35: 5000 | H35: 132 | I35: 5000
C36: 23 | D36: 45085 | E36: 144 | F36: Mine Chem | G36: 2000 | H36: 171.5 | J36: 2000
C37: 24 | D37: 45085 | E37: 145 | F37: Om Shakti | G37: 500 | H37: 169 | J37: 500
C38: 25 | D38: 45085 | E38: 146 | F38: Om Shakti | G38: 125 | H38: 135, 195 | I38: 100 | L38: 25
C39: 26 | D39: 45085 | E39: GTC 27 | F39: AP Bond | G39: 1000 | H39: 197 | M39: 1000
C40: 27 | D40: 45086 | E40: 148 | F40: Target | G40: 300 | H40: 130 | I40: 300
C41: 28 | D41: 45086 | E41: 149 | F41: Siva Chem | G41: 500 | H41: 188 | O41: 500
C42: 29 | D42: 45087 | E42: 150 | F42: Mine Chem | G42: 100 | H42: 137 | I42: 100
C43: 30 | D43: 45089 | E43: 152 | F43: SKR | G43: 3000 | H43: 125 | I43: 3000
C44: 31 | D44: 45089 | E44: 153 | F44: Kanha | G44: 300 | H44: 135 | I44: 300
C45: 32 | D45: 45089 | E45: 154 | F45: Mine Chem | G45: 25 | H45: 185 | O45: 25
C46: 33 | D46: 45090 | E46: 155 | F46: Deepak Enterprise | G46: 2000 | H46: 189 | P46: 2000
...

Sheet July 2023
D4: July 2023 Sales in Nutsell | O4: Prime | P4: Off Grade | Q4: Total
D5: Grades | E5: Off Grade | F5: 1799 | G5: 2099 | H5: 2699 | I5: 588 | J5: 2088 | K5: 2488 | L5: 2688 | M5: 3099 | N5: TOTAL
D6: Qty | E6: ='July 2023'!$I$84 -> 22880 | F6: ='July 2023'!$J$84 -> 16775 | G6: ='July 2023'!$K$84 -> 0 | H6: ='July 2023'!$L$84 -> 12675 | I6: ='July 2023'!$M$84 -> 1125 | J6: ='July 2023'!$N$84 -> 18225 | K6: ='July 2023'!$O$84 -> 15925 | L6: ='July 2023'!$P$84 -> 8150 | M6: ='July 2023'!$Q$84 -> 1650 | N6: =SUM(E6:M6) -> 97405 | O6: =SUM(F6:M6) -> 74525 | P6: =E6 -> 22880 | Q6: =SUM(O6,P6) -> 97405
D7: Avg Sales PK
D8: Profit PK
D9: Total
C13: Srl No | D13: Date | E13: Inv No | F13: Party | G13: Qty | H13: Price | I13: Off Grade | J13: 1799 | K13: 2099 | L13: 2699 | M13: 588 | N13: 2088 | O13: 2488 | P13: 2688 | Q13: 3099 | T13: Off Grade Stocks And Sales
C14: 1 | D14: 45108 | E14: 195 | F14: Divysai | G14: 250 | H14: 169 | O14: 250 | T14: New Input
C15: 2 | D15: 45108 | E15: 196 | F15: Vrinda Chem | G15: 3000 | H15: 167 | O15: 3000 | T15: Srl No. | U15: Date | V15: Details | W15: Qty
C16: 3 | D16: 45108 | E16: RR | F16: Patidar Adh | G16: 1000 | H16: 179 | L16: 500 | P16: 500 | T16: 1 | U16: 45122 | V16: JP Impex | W16: 17001
C17: 4 | D17: 45110 | E17: 197 | F17: Mine Chem | G17: 1000 | H17: 151 | J17: 1000 | T17: 2 | U17: 45135 | V17: JP Impex | W17: 18607
C18: 5 | D18: 45112 | E18: 200 | F18: Sagar Dye | G18: 650 | H18: 172 | O18: 650 | T18: 3
C19: 6 | D19: 45112 | E19: RR | F19: Meet Sach | G19: 200 | H19: 162 | J19: 200 | T19: 4
C20: 7 | D20: 45113 | E20: 202 | F20: Kanha | G20: 1000 | H20: 168 | N20: 1000 | T20: 5
C21: 8 | D21: 45113 | E21: 203 | F21: Aditya | G21: 3125 | H21: 167, 162 | M21: 1125 | O21: 2000 | T21: 6
C22: 9 | D22: 45113 | E22: 204 | F22: Akshat | G22: 145 | H22: 130, 185 | I22: 120 | L22: 25 | T22: 7
C23: 10 | D23: 45113 | E23: 205 | F23: KDM | G23: 100 | H23: 128 | I23: 100 | T23: 8
C24: 11 | D24: 45114 | E24: 206 | F24: Popular Chemical | G24: 150 | H24: 172 | P24: 150
C25: 12 | D25: 45114 | E25: 207 | F25: Kanha | G25: 300 | H25: 130 | I25: 300 | T25: Total New Input:- | W25: =SUM(W16:W23) -> 35608
C26: 13 | D26: 45115 | E26: 208 | F26: Mine Chem | G26: 20 | H26: 135 | I26: 20 | T26: Old Stock C/F:- | W26: 108793
C27: 14 | D27: 45115 | E27: GTC 31 | F27: Veena | G27: 625 | H27: 170 | O27: 625 | T27: Total Stocks New & Old :- | W27: =SUM(W25,W26) -> 144401
C28: 15 | D28: 45116 | E28: 209 | F28: Can Image | G28: 5000 | H28: 192 | N28: 5000 | T28: LESS SALES: (as per sales sheet) | W28: ='July 2023'!$I$84 -> 22880
C29: 16 | D29: 45117 | E29: 210 | F29: Fortune | G29: 500 | H29: 190 | L29: 500
C30: 17 | D30: 45117 | E30: 211 | F30: Aditya | G30: 5000 | H30: 148 | J30: 5000 | T30: NET QTY AVAILABLE: | W30: =SUM(W27-W28) -> 121521
C31: 18 | D31: 45118 | E31: 212 | F31: Chandan | G31: 2000 | H31: 158 | O31: 2000
C32: 19 | D32: 45118 | E32: 213 | F32: Mangalam | G32: 340 | H32: 125, 157, 170 | I32: 140 | L32: 150 | O32: 50
C33: 20 | D33: 45119 | E33: 214 | F33: Akshat Chem | G33: 1000 | H33: 162 | P33: 1000
C34: 21 | D34: 45120 | E34: 215 | F34: Paresh Pure | G34: 1025 | H34: 159 | N34: 1025
C35: 22 | D35: 45122 | E35: 218 | F35: Surya | G35: 2000 | H35: 185 | P35: 2000
C36: 23 | D36: 45124 | E36: 219 | F36: Jupiter | G36: 300 | H36: 154 | O36: 300
C37: 24 | D37: 45124 | E37: 220 | F37: Mine Chem | G37: 200 | H37: 122 | I37: 200
C38: 25 | D38: 45125 | E38: 221 | F38: Siva Chem | G38: 25 | H38: 150 | J38: 25
C39: 26 | D39: 45125 | E39: 222 | F39: Guruji | G39: 2500 | H39: 120, 165 | I39: 2000 | P39: 500
C40: 27 | D40: 45125 | E40: 223 | F40: Mine Chem | G40: 1000 | H40: 147.5 | J40: 1000
C41: 28 | D41: 45125 | E41: 224 | F41: Aditya | G41: 9000 | H41: 144, 155, 154 | J41: 5000 | N41: 2000 | O41: 2000
C42: 29 | D42: 45128 | E42: 227 | F42: Kanha | G42: 500 | H42: 158 | N42: 500
C43: 30 | D43: 45128 | E43: 228 | F43: Vasudha Colors | G43: 1000 | H43: 175 | P43: 1000
C44: 31 | D44: 45128 | E44: 229 | F44: Aditya | G44: 3000 | H44: 154 | L44: 3000
C45: 32 | D45: 45128 | E45: 230 | F45: Siva Chem | G45: 10000 | H45: 119 | I45: 10000
C46: 33 | D46: 45128 | E46: 231 | F46: Pearl | G46: 500 | H46: 150 | N46: 500
...

Sheet Aug 2023
D6: August 2023 Sales in Nutsell | O6: Prime | P6: Off Grade | Q6: Total
D7: Grades | E7: Off Grade | F7: 1799 | G7: 2099 | H7: 2699 | I7: 588 | J7: 2088 | K7: 2488 | L7: 2688 | M7: 3099 | N7: TOTAL
D8: Qty | E8: ='Aug 2023'!$I$87 -> 16920 | F8: ='Aug 2023'!$J$87 -> 20325 | G8: ='Aug 2023'!$K$87 -> 0 | H8: ='Aug 2023'!$L$87 -> 14400 | I8: ='Aug 2023'!$M$87 -> 500 | J8: ='Aug 2023'!$N$87 -> 8525 | K8: ='Aug 2023'!$O$87 -> 10650 | L8: ='Aug 2023'!$P$87 -> 11075 | M8: ='Aug 2023'!$Q$87 -> 3375 | N8: =SUM(E8:M8) -> 85770 | O8: =SUM(F8:M8) -> 68850 | P8: =E8 -> 16920 | Q8: =SUM(O8,P8) -> 85770
D9: Avg Sales PK
D10: Profit PK
D11: Total
C15: Srl No | D15: Date | E15: Inv No | F15: Party | G15: Qty | H15: Price | I15: Off Grade | J15: 1799 | K15: 2099 | L15: 2699 | M15: 588 | N15: 2088 | O15: 2488 | P15: 2688 | Q15: 3099 | T15: Off Grade Stocks And Sales
C16: 1 | D16: 45139 | E16: 269 | F16: Ankush | G16: 1000 | H16: 154 | N16: 1000 | T16: New Input
C17: 2 | D17: 45139 | E17: 270 | F17: Agarwal | G17: 500 | H17: 153 | O17: 500 | T17: Srl No. | U17: Date | V17: Details | W17: Qty
C18: 3 | D18: 45139 | E18: 271 | F18: Kunal Dye | G18: 1500 | H18: 156 | L18: 1500 | T18: 1 | U18: 45149 | V18: IMP 19 - 2117 | W18: 20444
C19: 4 | D19: 45139 | E19: 272 | F19: Popular Chemical | G19: 1000 | H19: 159 | P19: 1000 | T19: 2
C20: 5 | D20: 45139 | E20: 273 | F20: Divysai | G20: 200 | H20: 156 | O20: 200 | T20: 3
C21: 6 | D21: 45140 | E21: 276 | F21: Popular Chemical | G21: 3000 | H21: 157 | L21: 3000 | T21: 4
C22: 7 | D22: 45140 | E22: 277 | F22: Sagar Corp | G22: 500 | H22: 157 | O22: 500 | T22: 5
C23: 8 | D23: 45141 | E23: 278 | F23: Uma Agen | G23: 2000 | H23: 145 | J23: 2000 | T23: 6
C24: 9 | D24: 45141 | E24: 279 | F24: Aadinath | G24: 500 | H24: 155 | O24: 500 | T24: 7
C25: 10 | D25: 45141 | E25: 280 | F25: Kanha | G25: 300 | H25: 125 | I25: 300 | T25: 8
C26: 11 | D26: 45142 | E26: 283 | F26: BSB Indus | G26: 1000 | H26: 148, 162, 162 | J26: 300 | N26: 500 | O26: 200
C27: 12 | D27: 45142 | E27: 284 | F27: Mine Chem | G27: 1000 | H27: 147 | J27: 1000 | T27: Total New Input:- | W27: =SUM(W18:W25) -> 20444
C28: 13 | D28: 45143 | E28: 285 | F28: Kunal Dye | G28: 2400 | H28: 158 | L28: 2400 | T28: Old Stock C/F:- | W28: 121521
C29: 14 | D29: 45143 | E29: 286 | F29: Soham | G29: 500 | H29: 160 | N29: 500 | T29: Total Stocks New & Old :- | W29: =SUM(W27,W28) -> 141965
C30: 15 | D30: 45143 | E30: 287 | F30: Fortune | G30: 500 | H30: 170 | P30: 500 | T30: LESS SALES: (as per sales sheet) | W30: ='Aug 2023'!$I$87 -> 16920
C31: 16 | D31: 45143 | E31: 288 | F31: Jay Organics | G31: 100 | H31: 130 | I31: 100
C32: 17 | D32: 45145 | E32: 289 | F32: KDM | G32: 250 | H32: 100, 165 | I32: 200 | P32: 50 | T32: NET QTY AVAILABLE: | W32: =SUM(W29-W30) -> 125045
C33: 18 | D33: 45148 | E33: 293 | F33: AP Enterprise | G33: 300 | H33: 185, 180 | P33: 275 | Q33: 75
C34: 19 | D34: 45148 | E34: 294 | F34: Mine Chem | G34: 100 | H34: 172 | P34: 100
C35: 20 | D35: 45148 | E35: 295 | F35: Pearl | G35: 2000 | H35: 153 | N35: 2000
C36: 21 | D36: 45149 | E36: 37 GTC | F36: Aditya | G36: 5000 | H36: 148.5 | J36: 5000
C37: 22 | D37: 45152 | E37: 297 | F37: Fortune | G37: 500 | H37: 170 | P37: 500
C38: 23 | D38: 45152 | E38: 298 | F38: Seamless | G38: 150 | H38: 185 | P38: 150
C39: 24 | D39: 45152 | E39: RR | F39: Shri Ganpatye | G39: 200 | H39: 190 | O39: 200
C40: 25 | D40: 45155 | E40: 38 GTC | F40: Veena | G40: 500 | H40: 170 | O40: 500
C41: 26 | D41: 45156 | E41: 300 | F41: Mine Chem | G41: 100 | H41: 152 | J41: 100
C42: 27 | D42: 45156 | E42: 301 | F42: Guruji | G42: 1000 | H42: 169 | Q42: 1000
C43: 28 | D43: 45156 | E43: 302 | F43: Giriraj | G43: 1000 | H43: 124 | I43: 1000
C44: 29 | D44: 45156 | E44: 307 | F44: Surya | G44: 4250 | H44: 185 | P44: 4250
C45: 30 | D45: 45156 | E45: 308 | F45: SKS Fine | G45: 200 | H45: 164 | N45: 200
C46: 31 | D46: 45157 | E46: 312 | F46: Jai Aravali | G46: 4500 | H46: 150 | J46: 4500
C47: 32 | D47: 45160 | E47: 315 | F47: Divysai | G47: 500 | H47: 158 | N47: 500
C48: 33 | D48: 45160 | E48: 316 | F48: Darshan | G48: 220 | H48: 125 | I48: 220
...

Sheet Sept 2023
D7: September 2023 Sales in Nutsell | O7: Prime | P7: Off Grade | Q7: Total
D8: Grades | E8: Off Grade | F8: 1799 | G8: 2099 | H8: 2699 | I8: 588 | J8: 2088 | K8: 2488 | L8: 2688 | M8: 3099 | N8: TOTAL
D9: Qty | E9: ='Sept 2023'!$I$88 -> 42020 | F9: ='Sept 2023'!$J$88 -> 10100 | G9: ='Sept 2023'!$K$88 -> 0 | H9: ='Sept 2023'!$L$88 -> 500 | I9: ='Sept 2023'!$M$88 -> 8500 | J9: ='Sept 2023'!$N$88 -> 25100 | K9: ='Sept 2023'!$O$88 -> 13875 | L9: ='Sept 2023'!$P$88 -> 4525 | M9: ='Sept 2023'!$Q$88 -> 5000 | N9: =SUM(E9:M9) -> 109620 | O9: =SUM(F9:M9) -> 67600 | P9: =E9 -> 42020 | Q9: =SUM(O9,P9) -> 109620
D10: Old Stck CF | E10: 125045 | F10: 17475 | G10: 0 | H10: 500 | I10: 8500 | J10: 13250 | K10: 225 | L10: 4300 | M10: 5000 | N10: =SUM(E10:M10) -> 174295 | O10: =SUM(F10:M10) -> 49250 | P10: =E10 -> 125045 | Q10: =SUM(O10,P10) -> 174295
D11: New Input In Sept | E11: =W28 -> 97643 | J11: 18000 | K11: 18000 | N11: =SUM(E11:M11) -> 133643 | O11: =SUM(F11:M11) -> 36000 | P11: =E11 -> 97643 | Q11: =SUM(O11,P11) -> 133643
D12: Net Stocks CF | E12: =SUM(E10+E11-E9) -> 180668 | F12: =SUM(F10+F11-F9) -> 7375 | G12: =SUM(G10+G11-G9) -> 0 | H12: =SUM(H10+H11-H9) -> 0 | I12: =SUM(I10+I11-I9) -> 0 | J12: =SUM(J10+J11-J9) -> 6150 | K12: =SUM(K10+K11-K9) -> 4350 | L12: =SUM(L10+L11-L9) -> -225 | M12: =SUM(M10+M11-M9) -> 0 | N12: =SUM(E12:M12) -> 198318 | O12: =SUM(F12:M12) -> 17650 | P12: =E12 -> 180668 | Q12: =SUM(O12,P12) -> 198318
C16: Srl No | D16: Date | E16: Inv No | F16: Party | G16: Qty | H16: Price | I16: Off Grade | J16: 1799 | K16: 2099 | L16: 2699 | M16: 588 | N16: 2088 | O16: 2488 | P16: 2688 | Q16: 3099 | T16: Off Grade Stocks And Sales
C17: 1 | D17: 45170 | E17: 342 | F17: Ankush | G17: 1500 | H17: 169 | Q17: 1500 | T17: New Input
C18: 2 | D18: 45170 | E18: 343 | F18: Chemicare | G18: 3500 | H18: 171 | Q18: 3500 | T18: Srl No. | U18: Date | V18: Details | W18: Qty
C19: 3 | D19: 45170 | E19: 344 | F19: Siva Chem | G19: 500 | H19: 163 | P19: 500 | T19: 1 | U19: 45188 | V19: Crab Legs | W19: 12672
C20: 4 | D20: 45170 | E20: 345 | F20: Reliable | G20: 500 | H20: 164 | L20: 500 | T20: 2 | U20: 45190 | V20: Powder | W20: 18439
C21: 5 | D21: 45170 | E21: 346 | F21: Can Image | G21: 5000 | H21: 192 | N21: 5000 | T21: 3 | U21: 45191 | V21: Powder + Crystal | W21: 17513
C22: 6 | D22: 45171 | E22: 347 | F22: AP Bonding | G22: 3000 | H22: 325 | I22: 3000 | T22: 4 | U22: 45192 | V22: grade 325 | W22: 15513
C23: 7 | D23: 44961 | E23: 348 | F23: Guruji | G23: 1000 | H23: 161 | P23: 1000 | T23: 5 | U23: 45194 | V23: p+c | W23: 15987
C24: 8 | D24: 45020 | E24: 349 | F24: Om Shakhi | G24: 2000 | H24: 147 | J24: 2000 | T24: 6 | U24: 45194 | V24: p+c | W24: 17519
C25: 9 | D25: 45174 | E25: 351 | F25: Siva Chem | G25: 10000 | H25: 117 | I25: 10000 | T25: 7
C26: 10 | D26: 45174 | E26: 352 | F26: Fortune | G26: 520 | H26: 125, 185 | I26: 20 | P26: 500 | T26: 8
C27: 11 | D27: 45175 | E27: 354 | F27: Paresh Pure | G27: 1000 | H27: 160 | N27: 1000
C28: 12 | D28: 45177 | E28: 358 | F28: Growmore | G28: 400 | H28: 155 | J28: 400 | T28: Total New Input:- | W28: =SUM(W19:W26) -> 97643
C29: 13 | D29: 45177 | E29: 359 | F29: Divysai | G29: 500 | H29: 165 | N29: 500 | T29: Old Stock C/F:- | W29: 125045
C30: 14 | D30: 45178 | E30: 360 | F30: Popular | G30: 375 | H30: 158, 178 | J30: 250 | M30: 125 | T30: Total Stocks New & Old :- | W30: =SUM(W28,W29) -> 222688
C31: 15 | D31: 45178 | E31: RR | F31: Shri Ganpatye | G31: 225 | H31: 190 | P31: 225 | T31: LESS SALES: (as per sales sheet) | W31: ='Sept 2023'!$I$88 -> 42020
C32: 16 | D32: 45177 | E32: GTC 43 | F32: AP Bonding | G32: 2000 | H32: 157 | O32: 2000
C33: 17 | D33: 45177 | E33: 361 | F33: BSB Indus | G33: 5150 | H33: 115, 165 | I33: 4000 | N33: 1150 | T33: NET QTY AVAILABLE: | W33: =SUM(W30-W31) -> 180668
C34: 18 | D34: 45180 | E34: 363 | F34: Devanski | G34: 500 | H34: 165, 175 | M34: 250 | N34: 250
C35: 19 | D35: 45180 | E35: GTC 46 | F35: Veena | G35: 500 | H35: 170 | O35: 500
C36: 20 | D36: 45180 | E36: 364 | F36: Mine Chem | G36: 2500 | H36: 148.5 | J36: 2500
C37: 21 | D37: 45181 | E37: 365 | F37: Popular | G37: 3000 | H37: 178 | M37: 3000
C38: 22 | D38: 45181 | E38: 366 | F38: Popular | G38: 500 | H38: 158 | J38: 500
C39: 23 | D39: 45181 | E39: 367 | F39: Raj Chem | G39: 125 | H39: 180 | M39: 125
C40: 24 | D40: 45182 | E40: 368 | F40: Om Shakhi | G40: 1600 | H40: 114 | I40: 1600
C41: 25 | D41: 45182 | E41: 369 | F41: Growmore | G41: 400 | H41: 172 | O41: 400
C42: 26 | D42: 45183 | E42: 371 | F42: Popular | G42: 3000 | H42: 167 | N42: 3000
C43: 27 | D43: 45183 | E43: 372 | F43: Popular | G43: 500 | H43: 120 | I43: 500
C44: 28 | D44: 45184 | E44: 373 | F44: Siva Chem | G44: 10000 | H44: 117 | I44: 10000
C45: 29 | D45: 45184 | E45: 374 | F45: Fortune | G45: 500 | H45: 125 | I45: 500
C46: 30 | D46: 45184 | E46: 375 | F46: Mine Chem | G46: 250 | H46: 148.5 | J46: 250
C47: 31 | D47: 45184 | E47: 376 | F47: Kraft | G47: 500 | H47: 105 | I47: 500
C48: 32 | D48: 45184 | E48: GTC 47 | F48: Aditya | G48: 2000 | H48: 178 | M48: 2000
C49: 33 | D49: 45185 | E49: 379 | F49: KDM | G49: 1000 | H49: 170 | O49: 1000
...

Sheet Oct 2023
D5: October 2023 Sales in Nutsell | O5: Prime | P5: Off Grade | Q5: Total
D6: Grades | E6: Off Grade | F6: 1799 | G6: DENKA | H6: 2699 | I6: 588 | J6: 2088 | K6: 2488 | L6: 2688 | M6: 3099 | N6: TOTAL
D7: Qty | E7: ='Oct 2023'!$I$95 -> 66140 | F7: ='Oct 2023'!$J$95 -> 8450 | G7: ='Oct 2023'!$R$95 -> 5180 | H7: ='Oct 2023'!$L$95 -> 33725 | I7: ='Oct 2023'!$M$95 -> 0 | J7: ='Oct 2023'!$N$95 -> 20600 | K7: ='Oct 2023'!$O$95 -> 4150 | L7: ='Oct 2023'!$P$95 -> 2350 | M7: ='Oct 2023'!$Q$95 -> 9000 | N7: =SUM(E7:M7) -> 149595 | O7: =SUM(F7:M7) -> 83455 | P7: =E7 -> 66140 | Q7: =SUM(O7,P7) -> 149595
D8: Old Stck CF | E8: 180668 | F8: 7375 | G8: 0 | H8: 0 | I8: 0 | J8: 6150 | K8: 4150 | N8: =SUM(E8:M8) -> 198343 | O8: =SUM(F8:M8) -> 17675 | P8: =E8 -> 180668 | Q8: =SUM(O8,P8) -> 198343
D9: New Input In Oct | E9: =X26 -> 94665 | F9: 45000 | G9: 19000 | H9: 36000 | J9: 18000 | L9: 7500 | M9: 9000 | N9: =SUM(E9:M9) -> 229165 | O9: =SUM(F9:M9) -> 134500 | P9: =E9 -> 94665 | Q9: =SUM(O9,P9) -> 229165
D10: Net Stocks CF | E10: =SUM(E8+E9-E7) -> 209193 | F10: =SUM(F8+F9-F7) -> 43925 | G10: =SUM(G8+G9-G7) -> 13820 | H10: =SUM(H8+H9-H7) -> 2275 | I10: =SUM(I8+I9-I7) -> 0 | J10: =SUM(J8+J9-J7) -> 3550 | K10: =SUM(K8+K9-K7) -> 0 | L10: =SUM(L8+L9-L7) -> 5150 | M10: =SUM(M8+M9-M7) -> 0 | N10: =SUM(E10:M10) -> 277913 | O10: =SUM(F10:M10) -> 68720 | P10: =E10 -> 209193 | Q10: =SUM(O10,P10) -> 277913
C14: Srl No | D14: Date | E14: Inv No | F14: Party | G14: Qty | H14: Price | I14: Off Grade | J14: 1799 | K14: 2099 | L14: 2699 | M14: 588 | N14: 2088 | O14: 2488 | P14: 2688 | Q14: 3099 | R14: DENKA | U14: Off Grade Stocks And Sales
C15: 1 | D15: 45201 | E15: 406 | F15: Mine Chem | G15: 500 | H15: 120 | I15: 500 | U15: New Input
C16: 2 | D16: 45201 | E16: 408 | F16: Guruji | G16: 500 | H16: 119 | I16: 500 | U16: Srl No. | V16: Date | W16: Details | X16: Qty
C17: 3 | D17: 45201 | E17: 409 | F17: Chandan | G17: 3000 | H17: 123 | I17: 3000 | U17: 1 | V17: 45198 | W17: Superbond | X17: 8512
C18: 4 | D18: 45201 | E18: 410 | F18: Patel Adhesives | G18: 500 | H18: 117 | I18: 500 | U18: 2 | V18: 45198 | W18: Superbond | X18: 8582
C19: 5 | D19: 45202 | E19: 411 | F19: Swastik | G19: 600 | H19: 171 | O19: 600 | U19: 3 | V19: 45202 | W19: Powder | X19: 17447
C20: 6 | D20: 45202 | E20: 412 | F20: Swastik | G20: 1000 | H20: 171 | P20: 1000 | U20: 4 | V20: 45206 | W20: Powder | X20: 17944
C21: 7 | D21: 45202 | E21: 413 | F21: Fortune | G21: 500 | H21: 185 | P21: 500 | U21: 5 | V21: 45207 | W21: 80-35 | X21: 20997
C22: 8 | D22: 45203 | E22: 414 | F22: Popular | G22: 1300 | H22: 169 | N22: 1300 | U22: 6 | V22: 45230 | W22: 30-99 | X22: 21183
C23: 9 | D23: 45203 | E23: 415 | F23: Divysai | G23: 300 | H23: 163 | N23: 300 | U23: 7
C24: 10 | D24: 45203 | E24: RR | F24: Patidar | G24: 1000 | H24: 170 | L24: 1000 | U24: 8
C25: 11 | D25: 45203 | E25: 417 | F25: BSB Indus | G25: 1000 | H25: 154, 170, 172 | J25: 500 | L25: 300 | O25: 200
C26: 12 | D26: 45203 | E26: 418 | F26: Gautam Kabdhir | G26: 1000 | H26: 165 | N26: 1000 | U26: Total New Input:- | X26: =SUM(X17:X24) -> 94665
C27: 13 | D27: 45204 | E27: 419 | F27: Vrinda | G27: 15000 | H27: 113 | I27: 15000 | U27: Old Stock C/F:- | X27: 180668
C28: 14 | D28: 45204 | E28: 421 | F28: Surya | G28: 500 | H28: 159 | J28: 500 | U28: Total Stocks New & Old :- | X28: =SUM(X26,X27) -> 275333
C29: 15 | D29: 45204 | E29: 422 | F29: KDM | G29: 1000 | H29: 171 | O29: 1000 | U29: LESS SALES: (as per sales sheet) | X29: ='Oct 2023'!$I$95 -> 66140
C30: 16 | D30: 45204 | E30: 423 | F30: Raj Chem | G30: 1000 | H30: 164 | L30: 1000
C31: 17 | D31: 45204 | E31: GTC 53 | F31: Vrinda | G31: 4000 | H31: 162 | L31: 4000 | U31: NET QTY AVAILABLE: | X31: =SUM(X28-X29) -> 209193
C32: 18 | D32: 45204 | E32: GTC 54 | F32: Mine Chem | G32: 250 | H32: 150 | J32: 250
C33: 19 | D33: 45204 | E33: 424 | F33: Paresh Pure | G33: 500 | H33: 168 | N33: 500
C34: 20 | D34: 45205 | E34: 425 | F34: Paramount | G34: 15000 | H34: 112 | I34: 15000
C35: 21 | D35: 45205 | E35: 426 | F35: Reliable | G35: 1500 | H35: 170 | L35: 1500
C36: 22 | D36: 45206 | E36: 428 | F36: Raj Chem | G36: 1000 | H36: 158 | N36: 1000
C37: 23 | D37: 45206 | E37: GTC 55 | F37: Vrinda | G37: 5000 | H37: 178 | Q37: 5000
C38: 24 | D38: 45206 | E38: 429 | F38: Chemi Range | G38: 3000 | H38: 182 | Q38: 3000
C39: 26 | D39: 45206 | E39: 451 | F39: soham | G39: 500 | H39: 172 | O39: 500
C40: 27 | D40: 45208 | E40: GTC 56 | F40: AP Bonding | G40: 1000 | H40: 163.5 | L40: 1000
C41: 28 | D41: 45208 | E41: GTC 57 | F41: Veekay | G41: 3000 | H41: 170 | L41: 3000
C42: 29 | D42: 45208 | E42: GTC 58 | F42: Paresh Pure | G42: 3500 | H42: 162 | N42: 3500
C43: 30 | D43: 45208 | E43: GTC 59 | F43: Paresh Pure | G43: 500 | H43: 166 | N43: 500
C44: 31 | D44: 45208 | E44: 430 | F44: Seamless | G44: 150 | H44: 185 | P44: 150
C45: 32 | D45: 45208 | E45: 431 | F45: Vasudha | G45: 500 | H45: 120 | I45: 500
C46: 33 | D46: 45208 | E46: 432 | F46: KDM | G46: 600 | H46: 118 | I46: 600
C47: 34 | D47: 45208 | E47: 433 | F47: Raj Indus | G47: 1150 | H47: 164, 182 | L47: 1000 | Q47: 150
...

Sheet Nov 2023
D3: November 2023 Sales in Nutsell | O3: Prime | P3: Off Grade | Q3: Total
D4: Grades | E4: Off Grade | F4: 1799 | G4: 2699 | H4: 588 | I4: 2088 | J4: 2488 | K4: 2688 | L4: 3099 | M4: DENKA | N4: TOTAL
D5: Old Stck CF | E5: 209193 | F5: 43925 | G5: 2275 | H5: 0 | I5: 3550 | J5: 0 | K5: 5850 | L5: 0 | M5: 13820 | N5: =SUM(E5:M5) -> 278613 | O5: =SUM(F5:M5) -> 69420 | P5: =E5 -> 209193 | Q5: =O5+P5 -> 278613
D6: New Input In Oct | E6: =W24 -> 0 | G6: 18000 | H6: 8000 | J6: 18000 | K6: 10000 | L6: 18000 | N6: =SUM(E6:M6) -> 72000 | O6: =SUM(F6:M6) -> 72000 | P6: =E6 -> 0 | Q6: =O6+P6 -> 72000
D7: Sales In Nov | E7: ='Nov 2023'!$I$93 -> 14440 | F7: ='Nov 2023'!$J$93 -> 5850 | G7: ='Nov 2023'!$K$93 -> 4275 | H7: ='Nov 2023'!$L$93 -> 2800 | I7: ='Nov 2023'!$M$93 -> 3800 | J7: ='Nov 2023'!$N$93 -> 6275 | K7: ='Nov 2023'!$O$93 -> 6600 | L7: ='Nov 2023'!$P$93 -> 1600 | M7: ='Nov 2023'!$Q$93 -> 3300 | N7: =SUM(E7:M7) -> 48940 | O7: =SUM(F7:M7) -> 34500 | P7: =E7 -> 14440 | Q7: =SUM(O7,P7) -> 48940
D8: Net Stocks CF | E8: =SUM(E5,E6-E7) -> 194753 | F8: =SUM(F5,F6-F7) -> 38075 | G8: =SUM(G5,G6-G7) -> 16000 | H8: =SUM(H5,H6-H7) -> 5200 | I8: =SUM(I5,I6-I7) -> -250 | J8: =SUM(J5,J6-J7) -> 11725 | K8: =SUM(K5,K6-K7) -> 9250 | L8: =SUM(L5,L6-L7) -> 16400 | ... N8: =SUM(N5,N6-N7) -> 301673 | O8: =SUM(F8:M8) -> 106920 | P8: =E8 -> 194753 | Q8: =SUM(O8,P8) -> 301673
C12: Srl No | D12: Date | E12: Inv No | F12: Party | G12: Qty | H12: Price | I12: Off Grade | J12: 1799 | K12: 2699 | L12: 588 | M12: 2088 | N12: 2488 | O12: 2688 | P12: 3099 | Q12: DENKA | T12: Off Grade Stocks And Sales
C13: 1 | D13: 45231 | E13: 483 | F13: Paradise | G13: 2000 | H13: 163 | M13: 2000 | T13: New Input
C14: 2 | D14: 45231 | E14: 484 | F14: Surya | G14: 3000 | H14: 170 | O14: 3000 | T14: Srl No. | U14: Date | V14: Details | W14: Qty
C15: 3 | D15: 45231 | E15: RR | F15: Gurpreet | G15: 500 | H15: 119 | I15: 500 | T15: 1
C16: 4 | D16: 45231 | E16: 486 | F16: Divysai | G16: 350 | H16: 163 | M16: 350 | T16: 2
C17: 5 | D17: 45231 | E17: 487 | F17: KDM | G17: 720 | H17: 169, 117 | I17: 20 | N17: 700 | T17: 3
C18: 6 | D18: 45232 | E18: 488 | F18: Divysai | G18: 500 | H18: 163 | M18: 500 | T18: 4
C19: 7 | D19: 45232 | E19: RR | F19: Patidar | G19: 275 | H19: 169 | K19: 275 | T19: 5
C20: 8 | D20: 45232 | E20: GTC 77 78 | F20: Aditya | G20: 3000 | H20: 168, 178 | K20: 2000 | L20: 1000 | T20: 6
C21: 9 | D21: 45232 | E21: GTC 79 | F21: Mine Chem | G21: 1400 | H21: 147, 168 | J21: 1050 | N21: 350 | T21: 7
C22: 10 | D22: 45233 | E22: 491 | F22: Kanha | G22: 300 | H22: 125 | I22: 300 | T22: 8
C23: 11 | D23: 45234 | E23: 493 | F23: SKR | G23: 1200 | H23: 113 | I23: 1200
C24: 12 | D24: 45234 | E24: 494 | F24: Vasudha | G24: 1000 | H24: 184 | L24: 1000 | T24: Total New Input:- | W24: =SUM(W15:W22) -> 0
C25: 13 | D25: 45234 | E25: 495 | F25: KDM | G25: 600 | H25: 118, 205 | I25: 300 | Q25: 300 | T25: Old Stock C/F:- | W25: 209193
C26: 14 | D26: 45234 | E26: RR | F26: Meet Products | G26: 800 | H26: 118, 193, 150 | I26: 400 | J26: 300 | Q26: 100 | T26: Total Stocks New & Old :- | W26: =SUM(W24,W25) -> 209193
C27: 15 | D27: 45236 | E27: GTC 80 | F27: Veena | G27: 500 | H27: 173 | N27: 500 | T27: LESS SALES: (as per sales sheet) | W27: ='Nov 2023'!$I$93 -> 14440
C28: 16 | D28: 45236 | E28: GTC 82 | F28: Growmore | G28: 1000 | H28: 158, 200 | J28: 500 | Q28: 500
C29: 17 | D29: 45237 | E29: 497 | F29: Shree Mahalaxmi | G29: 160 | H29: 115 | I29: 160 | T29: NET QTY AVAILABLE: | W29: =SUM(W26-W27) -> 194753
C30: 18 | D30: 45237 | E30: 497 | F30: Mangalam Dye Chem | G30: 300 | H30: 120, 150 | I30: 200 | J30: 100
C31: 19 | D31: 45237 | E31: 499 | F31: Vasudha | G31: 3000 | H31: 120 | I31: 3000
C32: 20 | D32: 45238 | E32: 502 | F32: Fortune | G32: 500 | H32: 125 | I32: 500
C33: 21 | D33: 45241 | E33: 505 | F33: BSB Indus | G33: 4000 | H33: 115, 150, 175, 165, | I33: 3000 | J33: 400 | N33: 200 | O33: 400
C34: 22 | D34: 45237 | E34: GTC 83 | F34: Paresh Pure | G34: 700 | H34: 169 | M34: 700
C35: 23 | D35: 45245 | E35: 506 | F35: Popular | G35: 2000 | H35: 174 | N35: 2000
C36: 24 | D36: 45246 | E36: 508 | F36: Sagar Corp | G36: 1000 | H36: 116 | I36: 1000
C37: 26 | D37: 45247 | E37: 509 | F37: Shree Mahalaxmi | G37: 160 | H37: 115 | I37: 160
C38: 27 | D38: 45247 | E38: 511 | F38: KDM | G38: 1000 | H38: 170 | N38: 1000
C39: 28 | D39: 45247 | E39: 512 | F39: Popular | G39: 1000 | H39: 151 | J39: 1000
C40: 29 | D40: 45251 | E40: RR | F40: Patidar | G40: 500 | H40: 170 | P40: 500
C41: 30 | D41: 45251 | E41: 515 | F41: Divysai | G41: 500 | H41: 163 | N41: 500
C42: 31 | D42: 45251 | E42: GTC 84 | F42: Mine Chem | G42: 25 | H42: 168 | N42: 25
C43: 32 | D43: 45251 | E43: GTC 85 | F43: Growmore | G43: 1000 | H43: 158, 200 | J43: 500 | Q43: 500
C44: 33 | D44: 45251 | E44: 516 | F44: Fortune | G44: 500 | H44: 125 | I44: 500
C45: 34 | D45: 45251 | E45: GTC 86 | F45: Veekay | G45: 1000 | H45: 171 | N45: 1000
...

Sheet Dec 2023
D4: December 2023 Sales in Nutsell | O4: Prime | P4: Off Grade | Q4: Total
D5: Grades | E5: Off Grade | F5: 1799 | G5: 2699 | H5: 588 | I5: 2088 | J5: 2488 | K5: 2688 | L5: 3099 | M5: DENKA | N5: TOTAL
D6: Old Stck CF | E6: 194753 | F6: 38075 | G6: 16000 | H6: 5200 | I6: 0 | J6: 11725 | K6: 9250 | L6: 16400 | M6: 10520 | N6: =SUM(E6:M6) -> 301923 | O6: =SUM(F6:M6) -> 107170 | P6: =E6 -> 194753 | Q6: =O6+P6 -> 301923
D7: New Input In Dec | E7: =W32 -> 60360 | F7: =F18 -> 0 | G7: =G18 -> 9000 | H7: =H18 -> 27000 | I7: =I18 -> 36000 | J7: =J18 -> 36000 | K7: =K18 -> 18000 | L7: =L18 -> 18000 | M7: =M18 -> 19000 | N7: =N18 -> 163000 | O7: =SUM(F7:M7) -> 163000 | P7: =E7 -> 60360 | Q7: =O7+P7 -> 223360
D8: Sales In Dec | E8: ='Dec 2023'!$I$101 -> 69540 | F8: ='Dec 2023'!$J$101 -> 21450 | G8: ='Dec 2023'!$K$101 -> 12625 | H8: ='Dec 2023'!$L$101 -> 6120 | I8: ='Dec 2023'!$M$101 -> 22500 | J8: ='Dec 2023'!$N$101 -> 12025 | K8: ='Dec 2023'!$O$101 -> 4650 | L8: ='Dec 2023'!$P$101 -> 1000 | M8: ='Dec 2023'!$Q$101 -> 3560 | N8: =SUM(E8:M8) -> 153470 | O8: =SUM(F8:M8) -> 83930 | P8: =E8 -> 69540 | Q8: =SUM(O8,P8) -> 153470
D9: Net Stocks CF | E9: =SUM(E6,E7-E8) -> 185573 | F9: =SUM(F6,F7-F8) -> 16625 | G9: =SUM(G6,G7-G8) -> 12375 | H9: =SUM(H6,H7-H8) -> 26080 | I9: =SUM(I6,I7-I8) -> 13500 | J9: =SUM(J6,J7-J8) -> 35700 | K9: =SUM(K6,K7-K8) -> 22600 | L9: =SUM(L6,L7-L8) -> 33400 | ... N9: =SUM(N6,N7-N8) -> 311453 | O9: =SUM(F9:M9) -> 186240 | P9: =E9 -> 185573 | Q9: =SUM(O9,P9) -> 371813
C11: PRIME INPUT DETAILS | E11: GRADES | F11: 1799 | G11: 2699 | H11: 588 | I11: 2088 | J11: 2488 | K11: 2688 | L11: 3099 | M11: DENKA | N11: TOTAL | O11: FROM | P11: IMP NO
C12: SRL NO | D12: MAKE | E12: DATE | N12: =SUM(F12:M12) -> 0
C13: 1 | D13: Wanwei | E13: 45261 | I13: 18000 | N13: =SUM(F13:M13) -> 18000 | O13: GTC | P13: 12
C14: 2 | D14: IM | E14: 45268 | G14: 9000 | H14: 9000 | I14: 9000 | J14: 18000 | K14: 9000 | N14: =SUM(F14:M14) -> 54000 | O14: GTC | P14: 10
C15: 3 | D15: IM | E15: 45282 | H15: 18000 | I15: 9000 | J15: 18000 | K15: 9000 | N15: =SUM(F15:M15) -> 54000 | O15: GTC | P15: 13
C16: 4 | D16: Wanwei | E16: 45282 | L16: 18000 | N16: =SUM(F16:M16) -> 18000 | O16: SST | P16: 45
C17: 5 | D17: Denka | E17: 45269 | M17: 19000 | N17: =SUM(F17:M17) -> 19000 | O17: SST | P17: 47
C18: TOTAL | F18: =SUM(F12:F17) -> 0 | G18: =SUM(G12:G17) -> 9000 | H18: =SUM(H12:H17) -> 27000 | I18: =SUM(I12:I17) -> 36000 | J18: =SUM(J12:J17) -> 36000 | K18: =SUM(K12:K17) -> 18000 | L18: =SUM(L12:L17) -> 18000 | M18: =SUM(M12:M17) -> 19000 | N18: =SUM(F18:M18) -> 163000
C20: Srl No | D20: Date | E20: Inv No | F20: Party | G20: Qty | H20: Price | I20: Off Grade | J20: 1799 | K20: 2699 | L20: 588 | M20: 2088 | N20: 2488 | O20: 2688 | P20: 3099 | Q20: DENKA | T20: Off Grade Stocks And Sales
C21: 1 | D21: 45261 | E21: 533 | F21: Darshan | G21: 240 | H21: 115 | I21: 240 | T21: New Input
C22: 2 | D22: 45261 | E22: 534 | F22: Popular | G22: 300 | H22: 169 | N22: 300 | T22: Srl No. | U22: Date | V22: Details | W22: Qty
C23: 3 | D23: 45262 | E23: 535 | F23: Popular | G23: 6000 | H23: 172 | M23: 6000 | T23: 1 | U23: 45265 | V23: mix | W23: 17810
C24: 4 | D24: 45262 | E24: 536 | F24: KDM | G24: 1000 | H24: 171 | N24: 1000 | T24: 2 | U24: 45266 | V24: mix | W24: 15590
C25: 5 | D25: 45262 | E25: RR | F25: Meet Products | G25: 500 | H25: 117 | I25: 500 | T25: 3 | U25: 45274 | V25: superbond | W25: 10000
C26: 6 | D26: 45262 | E26: GTC 90 | F26: Growmore | G26: 880 | H26: 158, 200 | J26: 500 | Q26: 380 | T26: 4 | U26: 45291 | V26: mix - JP | W26: 16960
C27: 7 | D27: 45264 | E27: GTC 91 | F27: Aditya | G27: 6000 | H27: 140, 160 | J27: 4000 | K27: 2000 | T27: 5
C28: 8 | D28: 45264 | E28: GTC 92 | F28: Veena | G28: 1340 | H28: 172, 200 | N28: 500 | Q28: 840 | T28: 6
C29: 9 | D29: 45264 | E29: RR | F29: Gurpreet | G29: 1000 | H29: 120, 195 | I29: 700 | Q29: 300 | T29: 7
C30: 10 | D30: 45264 | E30: 539 | F30: Seamless | G30: 200 | H30: 185 | O30: 200 | T30: 8
C31: 11 | D31: 45264 | E31: 540 | F31: Reliable | G31: 1000 | H31: 165 | K31: 1000
C32: 12 | D32: 37961 | E32: RR | F32: Shri Ganpatye | G32: 100 | H32: 200 | Q32: 100 | T32: Total New Input:- | W32: =SUM(W23:W30) -> 60360
C33: 13 | D33: 45265 | E33: GTC 93 | F33: Aditya | G33: 5500 | H33: 156, 160 | M33: 3000 | N33: 2000 | O33: 500 | T33: Old Stock C/F:- | W33: 194753
C34: 14 | D34: 45267 | E34: 544 | F34: Mine Chem | G34: 1000 | H34: 143, 163 | J34: 500 | N34: 500 | T34: Total Stocks New & Old :- | W34: =SUM(W32,W33) -> 255113
C35: 15 | D35: 45267 | E35: 545 | F35: Chandan Synthetic | G35: 6000 | H35: 115, 139 | I35: 4000 | J35: 2000 | T35: LESS SALES: (as per sales sheet) | W35: ='Dec 2023'!$I$101 -> 69540
C36: 16 | D36: 45268 | E36: 546 | F36: Raj Inds | G36: 1000 | H36: 160 | P36: 1000
C37: 17 | D37: 45268 | E37: 547 | F37: Paradise | G37: 3000 | H37: 163 | L37: 3000 | T37: NET QTY AVAILABLE: | W37: =SUM(W34-W35) -> 185573
C38: 18 | D38: 45269 | E38: GTC 95 | F38: Paresh Pure | G38: 2000 | H38: 169 | M38: 2000
C39: 19 | D39: 45269 | E39: 548 | F39: Divysai | G39: 500 | H39: 161 | N39: 500
C40: 20 | D40: 45269 | E40: 550 | F40: Growmore | G40: 100 | H40: 172 | N40: 100
C41: 21 | D41: 45269 | E41: 551 | F41: Bhavya | G41: 3000 | H41: 157 | K41: 3000
C42: 22 | D42: 45269 | E42: 552 | F42: Siva | G42: 10000 | H42: 104 | I42: 10000
C43: 23 | D43: 45271 | E43: GTC 96 | F43: Veekay | G43: 1000 | H43: 161 | K43: 1000
C44: 24 | D44: 45271 | E44: GTC 97 | F44: Growmore | G44: 1000 | H44: 200 | Q44: 1000
C45: 26 | D45: 45271 | E45: 553 | F45: Vasudha | G45: 1500 | H45: 175, 172, 180 | L45: 500 | M45: 500 | O45: 500
...

Sheet Jan 2024
D4: Jan 2024 Sales in Nutsell | O4: Prime | P4: Off Grade | Q4: Total
D5: Grades | E5: Off Grade | F5: 1799 | G5: 2699 | H5: 588 | I5: 2088 | J5: 2488 | K5: 2688 | L5: 3099 | M5: DENKA | N5: TOTAL
D6: Old Stck CF | E6: 185573 | F6: 16625 | G6: 12375 | H6: 26080 | I6: 13500 | J6: 35700 | K6: 22600 | L6: 33400 | M6: 25960 | N6: =SUM(E6:M6) -> 371813 | O6: =SUM(F6:M6) -> 186240 | P6: =E6 -> 185573 | Q6: =O6+P6 -> 371813
D7: New Input In Dec | E7: =W32 -> 58678 | I7: 18000 | O7: =SUM(F7:M7) -> 18000 | P7: =E7 -> 58678 | Q7: =O7+P7 -> 76678
D8: Sales In Jan | E8: ='Jan 2024'!$I$101 -> 24780 | F8: ='Jan 2024'!$J$101 -> 11025 | G8: ='Jan 2024'!$K$101 -> 2950 | H8: ='Jan 2024'!$L$101 -> 4500 | I8: ='Jan 2024'!$M$101 -> 5500 | J8: ='Jan 2024'!$N$101 -> 5415 | K8: ='Jan 2024'!$O$101 -> 2550 | L8: ='Jan 2024'!$P$101 -> 0 | M8: ='Jan 2024'!$Q$101 -> 4580 | N8: =SUM(E8:M8) -> 61300 | O8: =SUM(F8:M8) -> 36520 | P8: =E8 -> 24780 | Q8: =SUM(O8,P8) -> 61300
D9: Net Stocks CF | E9: =SUM(E6,E7-E8) -> 219471 | F9: =SUM(F6,F7-F8) -> 5600 | G9: =SUM(G6,G7-G8) -> 9425 | H9: =SUM(H6,H7-H8) -> 21580 | I9: =SUM(I6,I7-I8) -> 26000 | J9: =SUM(J6,J7-J8) -> 30285 | K9: =SUM(K6,K7-K8) -> 20050 | L9: =SUM(L6,L7-L8) -> 33400 | M9: =SUM(M6,M7-M8) -> 21380 | N9: =SUM(N6+N7-N8) -> 310513 | O9: =SUM(F9:M9) -> 167720 | P9: =E9 -> 219471 | Q9: =SUM(O9,P9) -> 387191
C11: PRIME INPUT DETAILS | E11: GRADES | F11: 1799 | G11: 2699 | H11: 588 | I11: 2088 | J11: 2488 | K11: 2688 | L11: 3099 | M11: DENKA | N11: TOTAL | O11: FROM | P11: IMP NO
C12: SRL NO | D12: MAKE | E12: DATE | N12: =SUM(F12:M12) -> 0
C13: 1 | D13: Wanwei | E13: 45310 | I13: 18000
C14: 2 | D14: IM
C15: 3 | D15: IM
C16: 4 | D16: Wanwei
C17: 5 | D17: Denka
C18: TOTAL | F18: =SUM(F12:F17) -> 0 | G18: =SUM(G12:G17) -> 0 | H18: =SUM(H12:H17) -> 0 | I18: =SUM(I12:I17) -> 18000 | J18: =SUM(J12:J17) -> 0 | K18: =SUM(K12:K17) -> 0 | L18: =SUM(L12:L17) -> 0 | M18: =SUM(M12:M17) -> 0 | N18: =SUM(F18:M18) -> 18000
C20: Srl No | D20: Date | E20: Inv No | F20: Party | G20: Qty | H20: Price | I20: Off Grade | J20: 1799 | K20: 2699 | L20: 588 | M20: 2088 | N20: 2488 | O20: 2688 | P20: 3099 | Q20: DENKA | T20: Off Grade Stocks And Sales
C21: 1 | D21: 45292 | E21: 598 | F21: Mine Chem | G21: 1000 | H21: 146 | J21: 1000 | T21: New Input
C22: 2 | D22: 45292 | E22: 599 | F22: Akshat Corp | G22: 165 | H22: 120, 180 | I22: 140 | K22: 25 | T22: Srl No. | U22: Date | V22: Details | W22: Qty
C23: 3 | D23: 45293 | E23: GTC 114 | F23: Growmore | G23: 2500 | H23: 155, 200 | J23: 1500 | Q23: 1000 | T23: 1 | U23: 45296 | V23: mix JP | W23: 19115
C24: 4 | D24: 45294 | E24: RR | F24: Gurpreet | G24: 500 | H24: 120, 200 | I24: 300 | Q24: 200 | T24: 2 | U24: 45296 | V24: mix JP | W24: 20661
C25: 5 | D25: 45294 | E25: GTC 115 | F25: Veena | G25: 500 | H25: 171 | N25: 500 | T25: 3 | U25: 45301 | V25: mix JP | W25: 18902
C26: 6 | D26: 45294 | E26: GTC 116 | F26: Mine Chem | G26: 250 | H26: 151 | J26: 250 | T26: 4
C27: 7 | D27: 45295 | E27: 600 | F27: Vasudha | G27: 500 | H27: 180 | L27: 500 | T27: 5
C28: 8 | D28: 45295 | E28: 601 | F28: Surya Poly | G28: 2500 | H28: 152, 170, 200 | J28: 500 | O28: 1000 | Q28: 1000 | T28: 6
C29: 9 | D29: 45297 | E29: 603 | F29: Meet Products | G29: 200 | H29: 150 | J29: 200 | T29: 7
C30: 10 | D30: 45297 | E30: 604 | F30: KDM | G30: 700 | H30: 114 | I30: 700 | T30: 8
C31: 11 | D31: 45299 | E31: 605 | F31: Paresh Pure | G31: 1000 | H31: 116 | I31: 1000
C32: 12 | D32: 45299 | E32: 606 | F32: Akshat Corp | G32: 205 | H32: 120, 180 | I32: 180 | K32: 25 | T32: Total New Input:- | W32: =SUM(W23:W30) -> 58678
C33: 13 | D33: 45299 | E33: 607 | F33: BSB Indus | G33: 1000 | H33: 145 | J33: 1000 | T33: Old Stock C/F:- | W33: 185573
C34: 14 | D34: 45299 | E34: 608 | F34: Doshi Chem | G34: 300 | H34: 162 | K34: 300 | T34: Total Stocks New & Old :- | W34: =SUM(W32,W33) -> 244251
C35: 15 | D35: 45299 | E35: 609 | F35: Darshan | G35: 140 | H35: 115 | I35: 140 | T35: LESS SALES: (as per sales sheet) | W35: ='Jan 2024'!$I$101 -> 24780
C36: 16 | D36: 45299 | E36: GTC 117 | F36: Popular | G36: 1000 | H36: 145 | J36: 1000
C37: 17 | D37: 45301 | E37: 610 | F37: Shree Mahalaxmi | G37: 2000 | H37: 115 | I37: 2000 | T37: NET QTY AVAILABLE: | W37: =SUM(W34-W35) -> 219471
C38: 18 | D38: 45301 | E38: 611 | F38: Siva | G38: 10000 | H38: 105 | I38: 10000
C39: 19 | D39: 45302 | E39: 612 | F39: Can Image | G39: 3000 | H39: 170 | M39: 3000
C40: 20 | D40: 45303 | E40: RR | F40: Patidar | G40: 1000 | H40: 164 | K40: 1000
C41: 21 | D41: 45303 | E41: GTC 118 | F41: Popular | G41: 1000 | H41: 170, 194 | N41: 175 | O41: 525 | Q41: 300
C42: 22 | D42: 45304 | E42: 615 | F42: Fortune | G42: 1000 | H42: 120 | I42: 1000
C43: 23 | D43: 45306 | E43: 616 | F43: Anmol | G43: 25 | H43: 145 | J43: 25
C44: 24 | D44: 45306 | E44: 617 | F44: Empowera | G44: 1480 | H44: 188, 192 | Q44: 1480
C45: 26 | D45: 45306 | E45: 618 | F45: Guruji | G45: 1000 | H45: 115 | I45: 1000
...

Sheet Feb 24
D4: Feb 2024 Sales in Nutsell | O4: Prime | P4: Off Grade | Q4: Total
D5: Grades | E5: Off Grade | F5: 1799 | G5: 2699 | H5: 588 | I5: 2088 | J5: 2488 | K5: 2688 | L5: 3099 | M5: DENKA | N5: TOTAL
D6: Old Stck CF | E6: 219471 | F6: 5600 | G6: 9425 | H6: 21580 | I6: 26000 | J6: 30285 | K6: 20050 | L6: 33400 | M6: 21380 | N6: =SUM(E6:M6) -> 387191 | O6: =SUM(F6:M6) -> 167720 | P6: 219471 | Q6: =O6+P6 -> 387191
D7: New Input In Dec | E7: =W32 -> 0 | O7: =SUM(F7:M7) -> 0 | P7: =E7 -> 0 | Q7: =O7+P7 -> 0
D8: Sales In Feb | E8: ='Feb 24'!$I$101 -> 33780 | F8: ='Feb 24'!$J$101 -> 5575 | G8: ='Feb 24'!$K$101 -> 5500 | H8: ='Feb 24'!$L$101 -> 11460 | I8: ='Feb 24'!$M$101 -> 13025 | J8: ='Feb 24'!$N$101 -> 3300 | K8: ='Feb 24'!$O$101 -> 3500 | L8: ='Feb 24'!$P$101 -> 14975 | M8: ='Feb 24'!$Q$101 -> 6980 | N8: =SUM(E8:M8) -> 98095 | O8: =SUM(F8:M8) -> 64315 | P8: =E8 -> 33780 | Q8: =SUM(O8,P8) -> 98095
D9: Net Stocks CF | E9: =SUM(E6,E7-E8) -> 185691 | F9: =SUM(F6,F7-F8) -> 25 | G9: =SUM(G6,G7-G8) -> 3925 | H9: =SUM(H6,H7-H8) -> 10120 | I9: =SUM(I6,I7-I8) -> 12975 | J9: =SUM(J6,J7-J8) -> 26985 | K9: =SUM(K6,K7-K8) -> 16550 | L9: =SUM(L6,L7-L8) -> 18425 | M9: =SUM(M6,M7-M8) -> 14400 | N9: =SUM(N6+N7-N8) -> 289096 | O9: =SUM(F9:M9) -> 103405 | P9: 185691 | Q9: =SUM(O9,P9) -> 289096
C11: PRIME INPUT DETAILS | E11: GRADES | F11: 1799 | G11: 2699 | H11: 588 | I11: 2088 | J11: 2488 | K11: 2688 | L11: 3099 | M11: DENKA | N11: TOTAL | O11: FROM | P11: IMP NO
C12: SRL NO | D12: MAKE | E12: DATE | N12: =SUM(F12:M12) -> 0
C13: 1 | D13: Wanwei
C14: 2 | D14: IM
C15: 3 | D15: IM
C16: 4 | D16: Wanwei
C17: 5 | D17: Denka
C18: TOTAL | F18: =SUM(F12:F17) -> 0 | G18: =SUM(G12:G17) -> 0 | H18: =SUM(H12:H17) -> 0 | I18: =SUM(I12:I17) -> 0 | J18: =SUM(J12:J17) -> 0 | K18: =SUM(K12:K17) -> 0 | L18: =SUM(L12:L17) -> 0 | M18: =SUM(M12:M17) -> 0 | N18: =SUM(F18:M18) -> 0
C20: Srl No | D20: Date | E20: Inv No | F20: Party | G20: Qty | H20: Price | I20: Off Grade | J20: 1799 | K20: 2699 | L20: 588 | M20: 2088 | N20: 2488 | O20: 2688 | P20: 3099 | Q20: DENKA | T20: Off Grade Stocks And Sales
C21: 1 | D21: 45323 | E21: 646 | F21: Popular | G21: 2000 | H21: 145 | J21: 2000 | T21: New Input
C22: 2 | D22: 45324 | E22: 648 | F22: Om Neelkhant | G22: 1500 | H22: 119 | I22: 1900 | T22: Srl No. | U22: Date | V22: Details | W22: Qty
C23: 3 | D23: 45328 | E23: 653 | F23: Mine Chem | G23: 1325 | H23: 148, 160 | J23: 1125 | N23: 200 | T23: 1 | V23: mix JP
C24: 4 | D24: 45328 | E24: 654 | F24: Reliable | G24: 1500 | H24: 165 | K24: 1500 | T24: 2 | V24: mix JP
C25: 5 | D25: 45327 | E25: GC 130 | F25: Veena | G25: 600 | H25: 200 | Q25: 600 | T25: 3 | V25: mix JP
C26: 6 | D26: 45329 | E26: 655 | F26: BSB Indus | G26: 1000 | H26: 155, 158, 168 | M26: 600 | N26: 200 | O26: 200 | T26: 4
C27: 7 | D27: 45328 | E27: GTC 132 | F27: AP Bonding | G27: 5500 | H27: 154, 166 | K27: 1500 | M27: 4000 | T27: 5
C28: 8 | D28: 45330 | E28: 657 | F28: Vasudha | G28: 3000 | H28: 168 | K28: 2000 | O28: 1000 | T28: 6
C29: 9 | D29: 45331 | E29: 658 | F29: Kraft | G29: 1000 | H29: 112 | I29: 1000 | T29: 7
C30: 10 | D30: 45331 | E30: 659 | F30: Fortune | G30: 1120 | H30: 118, 125 | I30: 1120 | T30: 8
C31: 11 | D31: 45331 | E31: 660 | F31: Darshan | G31: 240 | H31: 115 | I31: 240
C32: 12 | D32: 45334 | E32: 661 | F32: Chemi Care | G32: 360 | H32: 167.5 | L32: 360 | T32: Total New Input:- | W32: =SUM(W23:W30) -> 0
C33: 13 | D33: 45334 | E33: 662 | F33: Patel Adhesives | G33: 17000 | H33: 164, 112 | I33: 1000 | O33: 1025 | P33: 14975 | T33: Old Stock C/F:- | W33: 185573
